{
 "cells": [
  {
   "cell_type": "code",
   "execution_count": 2,
   "id": "7f5ad89b-ace4-4279-a059-66a8c615975b",
   "metadata": {},
   "outputs": [
    {
     "name": "stdout",
     "output_type": "stream",
     "text": [
      "マイクに向かってタメ口で話しかけてください\n"
     ]
    },
    {
     "ename": "AttributeError",
     "evalue": "module 'speech_recognition' has no attribute 'UnkownValueError'",
     "output_type": "error",
     "traceback": [
      "\u001b[1;31m---------------------------------------------------------------------------\u001b[0m",
      "\u001b[1;31mUnknownValueError\u001b[0m                         Traceback (most recent call last)",
      "Cell \u001b[1;32mIn[2], line 17\u001b[0m\n\u001b[0;32m     16\u001b[0m \u001b[38;5;28;01mtry\u001b[39;00m:\n\u001b[1;32m---> 17\u001b[0m     recognized_text \u001b[38;5;241m=\u001b[39m \u001b[43mr\u001b[49m\u001b[38;5;241;43m.\u001b[39;49m\u001b[43mrecognize_google\u001b[49m\u001b[43m(\u001b[49m\u001b[43maudio\u001b[49m\u001b[43m,\u001b[49m\u001b[43m \u001b[49m\u001b[43mlanguage\u001b[49m\u001b[38;5;241;43m=\u001b[39;49m\u001b[38;5;124;43m'\u001b[39;49m\u001b[38;5;124;43mja\u001b[39;49m\u001b[38;5;124;43m'\u001b[39;49m\u001b[43m)\u001b[49m\n\u001b[0;32m     18\u001b[0m     \u001b[38;5;28mprint\u001b[39m(\u001b[38;5;124mf\u001b[39m\u001b[38;5;124m'\u001b[39m\u001b[38;5;124m音声認識結果「\u001b[39m\u001b[38;5;132;01m{\u001b[39;00mrecognized_text\u001b[38;5;132;01m}\u001b[39;00m\u001b[38;5;124m」\u001b[39m\u001b[38;5;124m'\u001b[39m)\n",
      "File \u001b[1;32m~\\AppData\\Local\\Programs\\Python\\Python312\\Lib\\site-packages\\speech_recognition\\recognizers\\google.py:263\u001b[0m, in \u001b[0;36mrecognize_legacy\u001b[1;34m(recognizer, audio_data, key, language, pfilter, show_all, with_confidence, endpoint)\u001b[0m\n\u001b[0;32m    260\u001b[0m output_parser \u001b[38;5;241m=\u001b[39m OutputParser(\n\u001b[0;32m    261\u001b[0m     show_all\u001b[38;5;241m=\u001b[39mshow_all, with_confidence\u001b[38;5;241m=\u001b[39mwith_confidence\n\u001b[0;32m    262\u001b[0m )\n\u001b[1;32m--> 263\u001b[0m \u001b[38;5;28;01mreturn\u001b[39;00m \u001b[43moutput_parser\u001b[49m\u001b[38;5;241;43m.\u001b[39;49m\u001b[43mparse\u001b[49m\u001b[43m(\u001b[49m\u001b[43mresponse_text\u001b[49m\u001b[43m)\u001b[49m\n",
      "File \u001b[1;32m~\\AppData\\Local\\Programs\\Python\\Python312\\Lib\\site-packages\\speech_recognition\\recognizers\\google.py:134\u001b[0m, in \u001b[0;36mOutputParser.parse\u001b[1;34m(self, response_text)\u001b[0m\n\u001b[0;32m    133\u001b[0m \u001b[38;5;28;01mdef\u001b[39;00m \u001b[38;5;21mparse\u001b[39m(\u001b[38;5;28mself\u001b[39m, response_text: \u001b[38;5;28mstr\u001b[39m):\n\u001b[1;32m--> 134\u001b[0m     actual_result \u001b[38;5;241m=\u001b[39m \u001b[38;5;28;43mself\u001b[39;49m\u001b[38;5;241;43m.\u001b[39;49m\u001b[43mconvert_to_result\u001b[49m\u001b[43m(\u001b[49m\u001b[43mresponse_text\u001b[49m\u001b[43m)\u001b[49m\n\u001b[0;32m    135\u001b[0m     \u001b[38;5;28;01mif\u001b[39;00m \u001b[38;5;28mself\u001b[39m\u001b[38;5;241m.\u001b[39mshow_all:\n",
      "File \u001b[1;32m~\\AppData\\Local\\Programs\\Python\\Python312\\Lib\\site-packages\\speech_recognition\\recognizers\\google.py:183\u001b[0m, in \u001b[0;36mOutputParser.convert_to_result\u001b[1;34m(response_text)\u001b[0m\n\u001b[0;32m    182\u001b[0m         \u001b[38;5;28;01mreturn\u001b[39;00m result[\u001b[38;5;241m0\u001b[39m]\n\u001b[1;32m--> 183\u001b[0m \u001b[38;5;28;01mraise\u001b[39;00m UnknownValueError()\n",
      "\u001b[1;31mUnknownValueError\u001b[0m: ",
      "\nDuring handling of the above exception, another exception occurred:\n",
      "\u001b[1;31mAttributeError\u001b[0m                            Traceback (most recent call last)",
      "Cell \u001b[1;32mIn[2], line 21\u001b[0m\n\u001b[0;32m     19\u001b[0m     teinei_text \u001b[38;5;241m=\u001b[39m tamego_to_teineigo(recognized_text)\n\u001b[0;32m     20\u001b[0m     \u001b[38;5;28mprint\u001b[39m(\u001b[38;5;124mf\u001b[39m\u001b[38;5;124m'\u001b[39m\u001b[38;5;124m丁寧語変換結果「\u001b[39m\u001b[38;5;132;01m{\u001b[39;00mteinei_text\u001b[38;5;132;01m}\u001b[39;00m\u001b[38;5;124m」\u001b[39m\u001b[38;5;124m'\u001b[39m)\n\u001b[1;32m---> 21\u001b[0m \u001b[38;5;28;01mexcept\u001b[39;00m \u001b[43msr\u001b[49m\u001b[38;5;241;43m.\u001b[39;49m\u001b[43mUnkownValueError\u001b[49m: \u001b[38;5;66;03m# 不明な値エラー（テキスト変換ができない）\u001b[39;00m\n\u001b[0;32m     22\u001b[0m     \u001b[38;5;28mprint\u001b[39m(\u001b[38;5;124m'\u001b[39m\u001b[38;5;124m認識できませんでした。\u001b[39m\u001b[38;5;124m'\u001b[39m)\n\u001b[0;32m     23\u001b[0m \u001b[38;5;28;01mexcept\u001b[39;00m sr\u001b[38;5;241m.\u001b[39mRequestError \u001b[38;5;28;01mas\u001b[39;00m e: \u001b[38;5;66;03m# ネットワークの関係で音声認識ができない\u001b[39;00m\n",
      "\u001b[1;31mAttributeError\u001b[0m: module 'speech_recognition' has no attribute 'UnkownValueError'"
     ]
    }
   ],
   "source": [
    "# 114\n",
    "import speech_recognition as sr\n",
    "\n",
    "def tamego_to_teineigo(text): # タメ口を丁寧語に変換する関数\n",
    "\n",
    "    return text\n",
    "\n",
    "r = sr.Recognizer()\n",
    "\n",
    "with sr.Microphone() as source: # with リソースを自動で管理する仕組み\n",
    "    r.adjust_for_ambient_noise(source, duration=1) # 1秒間の測定 \n",
    "        # adjust-noise: 周囲の環境音を測定し、音声認識の精度向上\n",
    "    print('マイクに向かってタメ口で話しかけてください')\n",
    "    audio = r.listen(source)\n",
    "\n",
    "try:\n",
    "    recognized_text = r.recognize_google(audio, language='ja')\n",
    "    print(f'音声認識結果「{recognized_text}」')\n",
    "    teinei_text = tamego_to_teineigo(recognized_text)\n",
    "    print(f'丁寧語変換結果「{teinei_text}」')\n",
    "except sr.UnkownValueError: # 不明な値エラー（テキスト変換ができない）\n",
    "    print('認識できませんでした。')\n",
    "except sr.RequestError as e: # ネットワークの関係で音声認識ができない\n",
    "    print('ネットワークエラーが発生しました。')"
   ]
  },
  {
   "cell_type": "code",
   "execution_count": 1,
   "id": "079ab167-2d94-419e-895f-68799a39c910",
   "metadata": {},
   "outputs": [
    {
     "name": "stdout",
     "output_type": "stream",
     "text": [
      "マイクに向かってタメ口で話しかけてください\n"
     ]
    },
    {
     "ename": "AttributeError",
     "evalue": "module 'speech_recognition' has no attribute 'UnkownValueError'",
     "output_type": "error",
     "traceback": [
      "\u001b[1;31m---------------------------------------------------------------------------\u001b[0m",
      "\u001b[1;31mUnknownValueError\u001b[0m                         Traceback (most recent call last)",
      "Cell \u001b[1;32mIn[1], line 17\u001b[0m\n\u001b[0;32m     16\u001b[0m \u001b[38;5;28;01mtry\u001b[39;00m:\n\u001b[1;32m---> 17\u001b[0m     recognized_text \u001b[38;5;241m=\u001b[39m \u001b[43mr\u001b[49m\u001b[38;5;241;43m.\u001b[39;49m\u001b[43mrecognize_google\u001b[49m\u001b[43m(\u001b[49m\u001b[43maudio\u001b[49m\u001b[43m,\u001b[49m\u001b[43m \u001b[49m\u001b[43mlanguage\u001b[49m\u001b[38;5;241;43m=\u001b[39;49m\u001b[38;5;124;43m'\u001b[39;49m\u001b[38;5;124;43mja\u001b[39;49m\u001b[38;5;124;43m'\u001b[39;49m\u001b[43m)\u001b[49m\n\u001b[0;32m     18\u001b[0m     rt \u001b[38;5;241m=\u001b[39m recognized_text\n",
      "File \u001b[1;32m~\\AppData\\Local\\Programs\\Python\\Python312\\Lib\\site-packages\\speech_recognition\\recognizers\\google.py:263\u001b[0m, in \u001b[0;36mrecognize_legacy\u001b[1;34m(recognizer, audio_data, key, language, pfilter, show_all, with_confidence, endpoint)\u001b[0m\n\u001b[0;32m    260\u001b[0m output_parser \u001b[38;5;241m=\u001b[39m OutputParser(\n\u001b[0;32m    261\u001b[0m     show_all\u001b[38;5;241m=\u001b[39mshow_all, with_confidence\u001b[38;5;241m=\u001b[39mwith_confidence\n\u001b[0;32m    262\u001b[0m )\n\u001b[1;32m--> 263\u001b[0m \u001b[38;5;28;01mreturn\u001b[39;00m \u001b[43moutput_parser\u001b[49m\u001b[38;5;241;43m.\u001b[39;49m\u001b[43mparse\u001b[49m\u001b[43m(\u001b[49m\u001b[43mresponse_text\u001b[49m\u001b[43m)\u001b[49m\n",
      "File \u001b[1;32m~\\AppData\\Local\\Programs\\Python\\Python312\\Lib\\site-packages\\speech_recognition\\recognizers\\google.py:134\u001b[0m, in \u001b[0;36mOutputParser.parse\u001b[1;34m(self, response_text)\u001b[0m\n\u001b[0;32m    133\u001b[0m \u001b[38;5;28;01mdef\u001b[39;00m \u001b[38;5;21mparse\u001b[39m(\u001b[38;5;28mself\u001b[39m, response_text: \u001b[38;5;28mstr\u001b[39m):\n\u001b[1;32m--> 134\u001b[0m     actual_result \u001b[38;5;241m=\u001b[39m \u001b[38;5;28;43mself\u001b[39;49m\u001b[38;5;241;43m.\u001b[39;49m\u001b[43mconvert_to_result\u001b[49m\u001b[43m(\u001b[49m\u001b[43mresponse_text\u001b[49m\u001b[43m)\u001b[49m\n\u001b[0;32m    135\u001b[0m     \u001b[38;5;28;01mif\u001b[39;00m \u001b[38;5;28mself\u001b[39m\u001b[38;5;241m.\u001b[39mshow_all:\n",
      "File \u001b[1;32m~\\AppData\\Local\\Programs\\Python\\Python312\\Lib\\site-packages\\speech_recognition\\recognizers\\google.py:183\u001b[0m, in \u001b[0;36mOutputParser.convert_to_result\u001b[1;34m(response_text)\u001b[0m\n\u001b[0;32m    182\u001b[0m         \u001b[38;5;28;01mreturn\u001b[39;00m result[\u001b[38;5;241m0\u001b[39m]\n\u001b[1;32m--> 183\u001b[0m \u001b[38;5;28;01mraise\u001b[39;00m UnknownValueError()\n",
      "\u001b[1;31mUnknownValueError\u001b[0m: ",
      "\nDuring handling of the above exception, another exception occurred:\n",
      "\u001b[1;31mAttributeError\u001b[0m                            Traceback (most recent call last)",
      "Cell \u001b[1;32mIn[1], line 22\u001b[0m\n\u001b[0;32m     20\u001b[0m     teinei_text \u001b[38;5;241m=\u001b[39m tamego_to_teineigo(recognized_text)\n\u001b[0;32m     21\u001b[0m     \u001b[38;5;28mprint\u001b[39m(\u001b[38;5;124mf\u001b[39m\u001b[38;5;124m'\u001b[39m\u001b[38;5;124m丁寧語変換結果「\u001b[39m\u001b[38;5;132;01m{\u001b[39;00mteinei_text\u001b[38;5;132;01m}\u001b[39;00m\u001b[38;5;124m」\u001b[39m\u001b[38;5;124m'\u001b[39m)\n\u001b[1;32m---> 22\u001b[0m \u001b[38;5;28;01mexcept\u001b[39;00m \u001b[43msr\u001b[49m\u001b[38;5;241;43m.\u001b[39;49m\u001b[43mUnkownValueError\u001b[49m: \u001b[38;5;66;03m# 不明な値エラー（テキスト変換ができない）\u001b[39;00m\n\u001b[0;32m     23\u001b[0m     \u001b[38;5;28mprint\u001b[39m(\u001b[38;5;124m'\u001b[39m\u001b[38;5;124m認識できませんでした。\u001b[39m\u001b[38;5;124m'\u001b[39m)\n\u001b[0;32m     24\u001b[0m \u001b[38;5;28;01mexcept\u001b[39;00m sr\u001b[38;5;241m.\u001b[39mRequestError \u001b[38;5;28;01mas\u001b[39;00m e: \u001b[38;5;66;03m# ネットワークの関係で音声認識ができない\u001b[39;00m\n",
      "\u001b[1;31mAttributeError\u001b[0m: module 'speech_recognition' has no attribute 'UnkownValueError'"
     ]
    }
   ],
   "source": [
    "# 114\n",
    "import speech_recognition as sr\n",
    "\n",
    "def tamego_to_teineigo(text): # タメ口を丁寧語に変換する関数\n",
    "\n",
    "    return text\n",
    "\n",
    "r = sr.Recognizer()\n",
    "\n",
    "with sr.Microphone() as source: # with リソースを自動で管理する仕組み\n",
    "    r.adjust_for_ambient_noise(source, duration=1) # 1秒間の測定 \n",
    "        # adjust-noise: 周囲の環境音を測定し、音声認識の精度向上\n",
    "    print('マイクに向かってタメ口で話しかけてください')\n",
    "    audio = r.listen(source)\n",
    "\n",
    "try:\n",
    "    recognized_text = r.recognize_google(audio, language='ja')\n",
    "    rt = recognized_text\n",
    "    print(f'音声認識結果「{recognized_text}」')\n",
    "    teinei_text = tamego_to_teineigo(recognized_text)\n",
    "    print(f'丁寧語変換結果「{teinei_text}」')\n",
    "except sr.UnkownValueError: # 不明な値エラー（テキスト変換ができない）\n",
    "    print('認識できませんでした。')\n",
    "except sr.RequestError as e: # ネットワークの関係で音声認識ができない\n",
    "    print('ネットワークエラーが発生しました。')\n",
    "filename = 'recognized_text'\n",
    "rt.write(filename, recognized_text)"
   ]
  },
  {
   "cell_type": "code",
   "execution_count": null,
   "id": "79dcdeee-4e9e-4a17-8cf4-7dda43317f95",
   "metadata": {},
   "outputs": [],
   "source": []
  }
 ],
 "metadata": {
  "kernelspec": {
   "display_name": "Python 3 (ipykernel)",
   "language": "python",
   "name": "python3"
  },
  "language_info": {
   "codemirror_mode": {
    "name": "ipython",
    "version": 3
   },
   "file_extension": ".py",
   "mimetype": "text/x-python",
   "name": "python",
   "nbconvert_exporter": "python",
   "pygments_lexer": "ipython3",
   "version": "3.12.4"
  }
 },
 "nbformat": 4,
 "nbformat_minor": 5
}
